Workbook
Name Slicer_Family__category: #N/A
Name Slicer_Income_category: #N/A
Name Slicer_Marital_Status: #N/A
Name Slicer_Recency_Category: #N/A

Sheet Sheet1
A3: Row Labels | B3: Sum of Z_Revenue
A4: 62-77 Snr Citizen | B4: 7766
A5: 46-61 Old | B5: 11759
A6: 30-45 Youth | B6: 4235
A7: 78-133 Elder | B7: 880
A8: Grand Total | B8: 24640
A28: Row Labels | B28: Sum of Total_purchase
A29: 2n Cycle | B29: 2802
A30: Basic | B30: 379
A31: Graduation | B31: 16894
A32: Master | B32: 5523
A33: PhD | B33: 7693
A34: Grand Total | B34: 33291
A47: Row Labels | B47: Sum of CampaignAccepted
A48: Absurd | B48: 3
A49: Alone | B49: 2
A50: Divorced | B50: 116
A51: Married | B51: 360
A52: Single | B52: 244
A53: Together | B53: 228
A54: Widow | B54: 47
A55: YOLO | B55: 1
A56: Grand Total | B56: 1001
A71: Row Labels | B71: Count of CampaignAccepted
A72: 1730 | B72: 1
A73: 2447 | B73: 1
A74: 3502 | B74: 1
A75: 4023 | B75: 1
A76: 4428 | B76: 1
A77: 4861 | B77: 1
A78: 5305 | B78: 1
A79: 5648 | B79: 1
A80: 6560 | B80: 1
A81: 6835 | B81: 1
A82: 7144 | B82: 1
A83: 7500 | B83: 12
... A2046: 51386 | B2046: 24
A2047: Grand Total | B2047: 2240
A2055: Sum of total_Revenue
A2056: 24640
...

Sheet Sheet6
A1: Bin | B1: Frequency
A2: 30 | B2: 2
A3: 32.191489 | B3: 8
A4: 34.382979 | B4: 18
A5: 36.574468 | B5: 33
A6: 38.765957 | B6: 59
A7: 40.957447 | B7: 69
A8: 43.148936 | B8: 112
A9: 45.340426 | B9: 84
A10: 47.531915 | B10: 92
A11: 49.723404 | B11: 129
A12: 51.914894 | B12: 172
A13: 54.106383 | B13: 222
... A48: 130.80851 | B48: 0
A49: More | B49: 1

Sheet Sheet8
A3: Row Labels | B3: Count of AcceptedCmp5
A4: 0 | B4: 2077
A5: 1 | B5: 163
A6: Grand Total | B6: 2240
A9: Row Labels | B9: Count of AcceptedCmp4
A10: 0 | B10: 2073
A11: 1 | B11: 167
A12: Grand Total | B12: 2240

Sheet Sheet9
A1: Bin | B1: Frequency
A2: 0 | B2: 28
A3: 2.106383 | B3: 52
A4: 4.212766 | B4: 56
A5: 6.3191489 | B5: 36
A6: 8.4255319 | B6: 37
A7: 10.531915 | B7: 50
A8: 12.638298 | B8: 50
A9: 14.744681 | B9: 46
A10: 16.851064 | B10: 37
A11: 18.957447 | B11: 39
A12: 21.06383 | B12: 67
A13: 23.170213 | B13: 41
... A48: 96.893617 | B48: 44
A49: More | B49: 59

Sheet Sheet10
A3: Row Labels | B3: Sum of total_Revenue | C3: Average of Age
A4: 30-45 Youth | B4: 1441 | C4: 39.229008
A5: 46-61 Old | B5: 2277 | C5: 53.483092
A6: 62-77 Snr Citizen | B6: 1419 | C6: 68.643411
A7: 78-133 Elder | B7: 143 | C7: 84.615385
A8: Grand Total | B8: 5280 | C8: 54.510417
B9: =GETPIVOTDATA("total_Revenue",$A$3) -> 5280 | C9: =GETPIVOTDATA("Average of Age",$A$3) -> 54.510417
A20: Row Labels | B20: Sum of Total Amounts (Qty)
A21: 2n Cycle | B21: 19947
A22: Basic | B22: 1039
A23: Graduation | B23: 153770
A24: Master | B24: 55953
A25: PhD | B25: 60403
A26: Grand Total | B26: 291112
B27: =GETPIVOTDATA("Total Amounts (Qty) ",$A$20) -> 291112
A37: Row Labels | B37: Sum of Response
A38: Single | B38: 106
A39: Grand Total | B39: 106
B47: =GETPIVOTDATA("Response",$A$37) -> 106

Sheet Sheet11
A1: Bin | B1: Frequency
A2: 30 | B2: 2
A3: 32.191489 | B3: 8
A4: 34.382979 | B4: 18
A5: 36.574468 | B5: 33
A6: 38.765957 | B6: 59
A7: 40.957447 | B7: 69
A8: 43.148936 | B8: 112
A9: 45.340426 | B9: 84
A10: 47.531915 | B10: 92
A11: 49.723404 | B11: 129
A12: 51.914894 | B12: 172
A13: 54.106383 | B13: 222
... A48: 130.80851 | B48: 0
A49: More | B49: 1

Sheet Sheet15
A1: Calculated Field
A2: Solve Order | B2: Field | C2: Formula
A3: 1 | B3: total_Revenue | C3: = SUM(Z_Revenue)
A4: 2 | B4: Total_customers | C4: = COUNT(ID )
A6: Calculated Item
A7: Solve Order | B7: Item | C7: Formula
A10: Note: | B10: When a cell is updated by more than one formula,
B11: the value is set by the formula with the last solve order.
B13: To change the solve order for multiple calculated items or fields,
B14: on the Options tab, in the Calculations group, click Fields, Items, & Sets, and then click Solve Order.

Sheet Sheet7
A3: Row Labels | B3: Count of AcceptedCmp1 | C3: Sum of Z_Revenue | D3: Sum of convert_rate
A4: 0 | B4: 356 | C4: 3916 | D4: 0.022767857
A5: 1 | B5: 31 | C5: 341 | D5: 0.0089285714
A6: Grand Total | B6: 387 | C6: 4257 | D6: 0.031696429
A8: Row Labels | B8: Count of AcceptedCmp2 | C8: Sum of total_Revenue | D8: Sum of convert_rate
A9: 0 | B9: 381 | C9: 4191 | D9: 0.030357143
A10: 1 | B10: 6 | C10: 66 | D10: 0.0013392857
A11: Grand Total | B11: 387 | C11: 4257 | D11: 0.031696429
A14: Row Labels | B14: Sum of total_Revenue | C14: Count of AcceptedCmp3 | D14: Sum of convert_rate
A15: 0 | B15: 759 | C15: 69 | D15: 0.0089285714
A16: 1 | B16: 143 | C16: 13 | D16: 0.0035714286
A17: Grand Total | B17: 902 | C17: 82 | D17: 0.0125
A20: Row Labels | B20: Count of AcceptedCmp4 | C20: Sum of total_Revenue | D20: Sum of convert_rate
A21: 0 | B21: 77 | C21: 847 | D21: 0.011607143
A22: 1 | B22: 5 | C22: 55 | D22: 0.00089285714
A23: Grand Total | B23: 82 | C23: 902 | D23: 0.0125 | E23: =GETPIVOTDATA("Sum of total_Revenue",$A$20,"AcceptedCmp4",1) -> 55 | F23: highest accepted campaign revenue
E24: =GETPIVOTDATA("AcceptedCmp4",$A$20,"AcceptedCmp4",1) -> 5 | F24: highest campaign accepted (4)
A26: Row Labels | B26: Count of AcceptedCmp5 | C26: Sum of Z_Revenue | D26: Sum of convert_rate
A27: 0 | B27: 74 | C27: 814 | D27: 0.009375
A28: 1 | B28: 8 | C28: 88 | D28: 0.003125
A29: Grand Total | B29: 82 | C29: 902 | D29: 0.0125
A34: Row Labels | B34: Average of convert_rate
A35: 0 | B35: 0.0089285714
A36: 1 | B36: 0.0035714286
A37: Grand Total | B37: 0.0125 | C37: =GETPIVOTDATA("convert_rate",$A$34) -> 0.0125 | D37: averag
A44: Row Labels | B44: Count of ID
A45: 195 | B45: 1
A46: 498 | B46: 1
A47: 975 | B47: 1
A48: 1012 | B48: 1
A49: 1162 | B49: 1
A50: 1381 | B50: 1
A51: 1456 | B51: 1
A52: 1506 | B52: 1
A53: 1542 | B53: 1
A54: 1726 | B54: 1
A55: 1839 | B55: 1
A56: 2114 | B56: 1
... A126: 11187 | B126: 1
A127: Grand Total | B127: 82
...

Sheet Sheet16
A1: Bin | B1: Frequency
A2: 0 | B2: 28
A3: 2.106383 | B3: 52
A4: 4.212766 | B4: 56
A5: 6.3191489 | B5: 36
A6: 8.4255319 | B6: 37
A7: 10.531915 | B7: 50
A8: 12.638298 | B8: 50
A9: 14.744681 | B9: 46
A10: 16.851064 | B10: 37
A11: 18.957447 | B11: 39
A12: 21.06383 | B12: 67
A13: 23.170213 | B13: 41
... A48: 96.893617 | B48: 44
A49: More | B49: 59

Sheet Sheet13
A2: Wines | B2: Fruits | C2: MeatProducts | D2: FishProducts | E2: SweetProducts | F2: GoldProducts
A3: Sum of MntWines | B3: Sum of MntFruits | C3: Sum of MntMeatProducts | D3: Sum of MntFishProducts | E3: Sum of MntSweetProducts | F3: Sum of MntGoldProds
A4: 555872 | B4: 45595 | C4: 279803 | D4: 65156 | E4: 46961 | F4: 82148
A5: =GETPIVOTDATA("Sum of MntWines",$A$3) -> 555872 | B5: =GETPIVOTDATA("Sum of MntFruits",$A$3) -> 45595 | C5: =GETPIVOTDATA("Sum of MntMeatProducts",$A$3) -> 279803 | D5: =GETPIVOTDATA("Sum of MntFishProducts",$A$3) -> 65156 | E5: =GETPIVOTDATA("Sum of MntSweetProducts",$A$3) -> 46961 | F5: =GETPIVOTDATA("Sum of MntGoldProds",$A$3) -> 82148
A24: Row Labels | B24: Sum of Total_purchase
A25: Family_with_more_children | B25: 28787
A26: Grand Total | B26: 28787
A43: Row Labels | B43: Sum of MntFishProducts | C43: Sum of MntGoldProds | D43: Sum of MntSweetProducts | E43: Sum of MntFruits | F43: Sum of MntMeatProducts | G43: Sum of MntWines
A44: high_income | B44: 65156 | C44: 82148 | D44: 46961 | E44: 45595 | F44: 279803 | G44: 555872
A45: Grand Total | B45: 65156 | C45: 82148 | D45: 46961 | E45: 45595 | F45: 279803 | G45: 555872
A68: Sum of Total Amounts (Qty) | B68: Sum of Total_purchase
A69: 1075535 | B69: 28787
A70: =GETPIVOTDATA("Sum of Total Amounts (Qty) ",$A$68) -> 1075535 | B70: =GETPIVOTDATA("Sum of Total_purchase",$A$68) -> 28787

Sheet Sheet21
A1: Bin | B1: Frequency | C1: class_int | D1: mid_point | E1: frq*mid point
A2: 1730 | B2: 1 | C2: =A3-A2 -> 14147.574 | D2: =(A3+A2)*0.5 -> 8803.7872 | E2: =B2*D2 -> 8803.7872
A3: 15877.574 | B3: 64 | C3: =A4-A3 -> 14147.574 | D3: =(A4+A3)*0.5 -> 22951.362 | E3: =B3*D3 -> 1468887.1
A4: 30025.149 | B4: 307 | C4: =A5-A4 -> 14147.574 | D4: =(A5+A4)*0.5 -> 37098.936 | E4: =B4*D4 -> 11389373
A5: 44172.723 | B5: 499 | C5: =A6-A5 -> 14147.574 | D5: =(A6+A5)*0.5 -> 51246.511 | E5: =B5*D5 -> 25572009
A6: 58320.298 | B6: 477 | C6: =A7-A6 -> 14147.574 | D6: =(A7+A6)*0.5 -> 65394.085 | E6: =B6*D6 -> 31192979
A7: 72467.872 | B7: 478 | C7: =A8-A7 -> 14147.574 | D7: =(A8+A7)*0.5 -> 79541.66 | E7: =B7*D7 -> 38020913
A8: 86615.447 | B8: 336 | C8: =A9-A8 -> 14147.574 | D8: =(A9+A8)*0.5 -> 93689.234 | E8: =B8*D8 -> 31479583
A9: 100763.02 | B9: 65 | C9: =A10-A9 -> 14147.574 | D9: =(A10+A9)*0.5 -> 107836.81 | E9: =B9*D9 -> 7009392.6
A10: 114910.6 | B10: 5 | C10: =A11-A10 -> 14147.574 | D10: =(A11+A10)*0.5 -> 121984.38 | E10: =B10*D10 -> 609921.91
A11: 129058.17 | B11: 0 | C11: =A12-A11 -> 14147.574 | D11: =(A12+A11)*0.5 -> 136131.96 | E11: =B11*D11 -> 0
A12: 143205.74 | B12: 0 | C12: =A13-A12 -> 14147.574 | D12: =(A13+A12)*0.5 -> 150279.53 | E12: =B12*D12 -> 0
A13: 157353.32 | B13: 4 | C13: =A14-A13 -> 14147.574 | D13: =(A14+A13)*0.5 -> 164427.11 | E13: =B13*D13 -> 657708.43
... A47: 638370.85 | B47: 0 | C47: =A48-A47 -> 14147.574 | D47: =(A48+A47)*0.5 -> 645444.64 | E47: =B47*D47 -> 0
A48: 652518.43 | B48: 0 | C48: =C47 -> 14147.574 | D48: =D47+C48 -> 659592.21 | E48: =B48*D48 -> 0
A49: More | B49: 1 | C49: =C48 -> 14147.574 | D49: =D48+C49 -> 673739.79 | E49: =B49*D49 -> 673739.79
B50: =SUM(B2:B49) -> 2240 | E50: =SUM(E2:E49) -> 1.4861903e+08
A51: mean | B51: =E50/B50 -> 66347.783
A52: median | B52: =(A48+A2)/2 -> 327124.21
A53: mode | B53: =A5 -> 44172.723

Sheet Sheet19
A3: Sum of NumCatalogPurchases | B3: Sum of NumStorePurchases | C3: Sum of NumDealsPurchases | D3: Sum of NumWebPurchases
A4: 5963 | B4: 12970 | C4: 5208 | D4: 9150
A5: =GETPIVOTDATA("Sum of NumCatalogPurchases",$A$3) -> 5963 | B5: =GETPIVOTDATA("Sum of NumStorePurchases",$A$3) -> 12970 | C5: =GETPIVOTDATA("Sum of NumDealsPurchases",$A$3) -> 5208 | D5: =GETPIVOTDATA("Sum of NumWebPurchases",$A$3) -> 9150
A31: Row Labels | B31: Sum of Total_purchase
A32: higher_webvists | B32: 14974
A33: lower_webvisits | B33: 18317
A34: Grand Total | B34: 33291
D46: =GETPIVOTDATA("Sum of Z_CostContact",$A$48,"Z_CostContact",3)/GETPIVOTDATA("Sum of Total_purchase",$A$48,"Z_CostContact",3) -> 0.20185636
A48: Row Labels | B48: Sum of Total_purchase | C48: Sum of Z_CostContact | D48: Sum of cpa
A49: 3 | B49: 33291 | C49: 6720 | D49: 0.20185636
A50: Grand Total | B50: 33291 | C50: 6720 | D50: 0.20185636
B51: =GETPIVOTDATA("Sum of Total_purchase",$A$48) -> 33291 | C51: =GETPIVOTDATA("Sum of Z_CostContact",$A$48) -> 6720 | D51: =GETPIVOTDATA("Sum of cpa",$A$48) -> 0.20185636
A59: Row Labels | B59: Sum of NumCatalogPurchases | C59: Sum of NumStorePurchases | D59: Sum of NumWebPurchases
A60: 0 | B60: 66 | C60: 147 | D60: 136
A61: 1 | B61: 63 | C61: 135 | D61: 94
A62: 2 | B62: 64 | C62: 155 | D62: 94
A63: 3 | B63: 70 | C63: 180 | D63: 122
A64: 4 | B64: 66 | C64: 178 | D64: 126
A65: 5 | B65: 40 | C65: 78 | D65: 59
A66: 6 | B66: 59 | C66: 139 | D66: 78
A67: 7 | B67: 49 | C67: 65 | D67: 46
A68: 8 | B68: 87 | C68: 171 | D68: 119
A69: 9 | B69: 57 | C69: 126 | D69: 127
A70: 10 | B70: 50 | C70: 131 | D70: 105
A71: 11 | B71: 52 | C71: 137 | D71: 97
... A159: 99 | B159: 31 | C159: 81 | D159: 59
A160: Grand Total | B160: 5963 | C160: 12970 | D160: 9150

Sheet Sheet23
A1: Bin | B1: Frequency
A2: 0 | B2: 11
A3: 0.42553191 | B3: 0
A4: 0.85106383 | B4: 0
A5: 1.2765957 | B5: 153
A6: 1.7021277 | B6: 0
A7: 2.1276596 | B7: 202
A8: 2.5531915 | B8: 0
A9: 2.9787234 | B9: 0
A10: 3.4042553 | B10: 205
A11: 3.8297872 | B11: 0
A12: 4.2553191 | B12: 218
A13: 4.6808511 | B13: 0
... A48: 19.574468 | B48: 0
A49: More | B49: 3

Sheet Sheet24
A1: Bin | B1: Frequency
A2: 0 | B2: 11
A3: 0.42553191 | B3: 0
A4: 0.85106383 | B4: 0
A5: 1.2765957 | B5: 153
A6: 1.7021277 | B6: 0
A7: 2.1276596 | B7: 202
A8: 2.5531915 | B8: 0
A9: 2.9787234 | B9: 0
A10: 3.4042553 | B10: 205
A11: 3.8297872 | B11: 0
A12: 4.2553191 | B12: 218
A13: 4.6808511 | B13: 0
... A48: 19.574468 | B48: 0
A49: More | B49: 3

Sheet customer retention
B2: LESS THAN 2 WKS | C2: AFTER A MONTH | D2: 2WKS -A MONTH
A3: #VALUE!
A23: Recency Category | B23: Mid-Recency
A25: Row Labels | B25: Sum of Total Amounts (Qty)
A26: 3790 | B26: 15
A27: 3955 | B27: 6
A28: 5329 | B28: 11
A29: 6679 | B29: 16
A30: 6961 | B30: 11
A31: 7196 | B31: 13
A32: 9291 | B32: 15
A33: 9725 | B33: 12
A34: 9931 | B34: 9
A35: 10241 | B35: 14
A36: Grand Total | B36: 122
A41: Count of acceptance category | B41: Column Labels
A42: Row Labels | B42: high Recency | C42: Grand Total
A43: 1 / 5 response accepted | B43: 229 | C43: 229
A44: 2/5 campaign accepted | B44: 73 | C44: 73
A45: 3/5 campaign accepted | B45: 29 | C45: 29
A46: 4/5 campaign accepted | B46: 24 | C46: 24
A47: high campaign response | B47: 5 | C47: 5
A48: low response | B48: 1138 | C48: 1138
A49: Grand Total | B49: 1498 | C49: 1498
A54: Count of acceptance category | B54: Column Labels
A55: Row Labels | B55: high purchase | C55: Grand Total
A56: 1 / 5 response accepted | B56: 6 | C56: 6
A57: 2/5 campaign accepted | B57: 3 | C57: 3
A58: 3/5 campaign accepted | B58: 1 | C58: 1
A59: low response | B59: 26 | C59: 26
A60: Grand Total | B60: 36 | C60: 36
A72: Row Labels | B72: Count of acceptance category
A73: 1 / 5 response accepted | B73: 370
A74: 2/5 campaign accepted | B74: 142
A75: 3/5 campaign accepted | B75: 51
A76: 4/5 campaign accepted | B76: 36
A77: high campaign response | B77: 10
A78: low response | B78: 1631
A79: Grand Total | B79: 2240
A102: ID | B102: (All)
...

Sheet Sheet17
A1: Bin | B1: Frequency
A2: 0 | B2: 4
A3: 0.93617021 | B3: 0
A4: 1.8723404 | B4: 4
A5: 2.8085106 | B5: 3
A6: 3.7446809 | B6: 0
A7: 4.6808511 | B7: 128
A8: 5.6170213 | B8: 145
A9: 6.5531915 | B9: 123
A10: 7.4893617 | B10: 149
A11: 8.4255319 | B11: 94
A12: 9.3617021 | B12: 102
A13: 10.297872 | B13: 80
... A48: 43.06383 | B48: 1
A49: More | B49: 1

Sheet Sheet14
A3: Sum of Income | B3: Column Labels
A4: Row Labels | B4: high_income | C4: Grand Total
A5: 1 / 5 response accepted | B5: 20961073 | C5: 20961073
A6: 2/5 campaign accepted | B6: 8724764 | C6: 8724764
A7: 3/5 campaign accepted | B7: 4001580 | C7: 4001580
A8: 4/5 campaign accepted | B8: 2957158 | C8: 2957158
A9: high campaign response | B9: 864344 | C9: 864344
A10: low response | B10: 79446116 | C10: 79446116
A11: Grand Total | B11: 116955035 | C11: 116955035
A28: Sum of Total_purchase | B28: Column Labels
A29: Row Labels | B29: high purchase | C29: Grand Total
A30: 1 / 5 response accepted | B30: 196 | C30: 196
A31: 2/5 campaign accepted | B31: 100 | C31: 100
A32: 3/5 campaign accepted | B32: 32 | C32: 32
A33: low response | B33: 863 | C33: 863
A34: Grand Total | B34: 1191 | C34: 1191
A47: Row Labels | B47: Sum of Total_purchase
A48: 1 / 5 response accepted | B48: 6360
A49: 2/5 campaign accepted | B49: 2564
A50: 3/5 campaign accepted | B50: 1071
A51: 4/5 campaign accepted | B51: 769
A52: high campaign response | B52: 210
A53: low response | B53: 22317
A54: Grand Total | B54: 33291

Sheet strategic bsnes Insights
A1: acceptance category | B1: high campaign response
A3: Row Labels | B3: Count of acceptance category
A4: Divorced | B4: 2
A5: Married | B5: 2
A6: Single | B6: 3
A7: Together | B7: 3
A8: Grand Total | B8: 10
A18: Purchase category | B18: high purchase
A20: Row Labels | B20: Count of Purchase category
A21: 30-45 Youth | B21: 1
A22: 46-61 Old | B22: 20
A23: 62-77 Snr Citizen | B23: 15
A24: Grand Total | B24: 36
A35: Income category | B35: high_income
A37: Row Labels | B37: Count of Income category
A38: Family_with_more_children | B38: 1984
A39: Family_with_one_child | B39: 255
A40: Grand Total | B40: 2239
A61: Income category | B61: high_income
A63: Row Labels | B63: Count of Income category
A64: 2n Cycle | B64: 203
A65: Basic | B65: 54
A66: Graduation | B66: 1126
A67: Master | B67: 370
A68: PhD | B68: 486
A69: Grand Total | B69: 2239
A80: Count of acceptance category | B80: Column Labels
A81: Row Labels | B81: 1 / 5 response accepted | C81: 2/5 campaign accepted | D81: 3/5 campaign accepted | E81: 4/5 campaign accepted | F81: high campaign response | G81: low response | H81: Grand Total
A82: 30-45 Youth | B82: 54 | C82: 37 | D82: 17 | E82: 8 | F82: 3 | G82: 266 | H82: 385
A83: 46-61 Old | B83: 163 | C83: 53 | D83: 22 | E83: 18 | F83: 1 | G83: 812 | H83: 1069
A84: 62-77 Snr Citizen | B84: 142 | C84: 38 | D84: 8 | E84: 10 | F84: 6 | G84: 502 | H84: 706
A85: 78-133 Elder | B85: 11 | C85: 14 | D85: 4 | G85: 51 | H85: 80
A86: Grand Total | B86: 370 | C86: 142 | D86: 51 | E86: 36 | F86: 10 | G86: 1631 | H86: 2240
A106: Count of acceptance category | B106: Column Labels
A107: Row Labels | B107: 1 / 5 response accepted | C107: 2/5 campaign accepted | D107: 3/5 campaign accepted | E107: 4/5 campaign accepted | F107: high campaign response | G107: low response | H107: Grand Total
A108: Absurd | D108: 1 | G108: 1 | H108: 2
A109: Alone | C109: 1 | G109: 2 | H109: 3
A110: Divorced | B110: 41 | C110: 18 | D110: 3 | E110: 5 | F110: 2 | G110: 163 | H110: 232
A111: Married | B111: 128 | C111: 54 | D111: 18 | E111: 15 | F111: 2 | G111: 647 | H111: 864
A112: Single | B112: 88 | C112: 35 | D112: 17 | E112: 5 | F112: 3 | G112: 332 | H112: 480
...

Sheet marketing_campaign
A1: ID | B1: Year_Birth | C1: Age | D1: Age_Group | E1: Education | F1: Marital_Status | G1: Family_size | H1: Family _category | I1: Income | J1: Income category | K1: Kidhome | L1: Teenhome | M1: Dt_Customer | N1: Recency | O1: Recency Category | P1: MntWines | Q1: MntFruits | R1: MntMeatProducts | S1: MntFishProducts | T1: MntSweetProducts | U1: MntGoldProds | V1: Total Amounts (Qty) | W1: NumDealsPurchases | X1: NumWebPurchases | Y1: NumCatalogPurchases | Z1: NumStorePurchases | AA1: Total_purchase | AB1: Purchase category | AC1: NumWebVisitsMonth | AD1: Category_of_web_visits | AE1: AcceptedCmp3 | AF1: AcceptedCmp4 | AG1: AcceptedCmp5 | AH1: AcceptedCmp1 | AI1: AcceptedCmp2 | AJ1: Complain | AK1: Z_CostContact | AL1: Z_Revenue | AM1: Response | AN1: CampaignAccepted | AO1: acceptance category
A2: 5524 | B2: 1957 | C2: =YEAR(TODAY())-B2 -> 69 | D2: {=_xlfn.IFS(AND(marketing_campaign[[#This Row],[Age]]>=30,marketing_campaign[[#This Row],[Age]]<=45),"30-45 Youth",AND(marketing_campaign[[#This Row],[Age]]>=46,marketing_campaign[[#This Row],[Age]]<=61),"46-61 Old",AND(marketing_campaign[[#This Row],[Age]]>=62,marketing_campaign[[#This Row],[Age]]<=77),"62-77 Snr Citizen",AND(marketing_campaign[[#This Row],[Age]]>=78,marketing_campaign[[#This Row],[Age]]<=133),"78-133 Elder")} -> 62-77 Snr Citizen | E2: Graduation | F2: Single | G2: {=_xlfn.IFS(marketing_campaign[[#This Row],[Marital_Status]]="Single",K2+L2+1,marketing_campaign[[#This Row],[Marital_Status]]="Together",K2+L2+2,marketing_campaign[[#This Row],[Marital_Status]]="Alone",K2+L2+1,marketing_campaign[[#This Row],[Marital_Status]]="Married",K2+L2+2,marketing_campaign[[#This Row],[Marital_Status]]="Divorced",K2+L2+1,marketing_campaign[[#This Row],[Marital_Status]]="YOLO",K2+L2+1,marketing_campaign[[#This Row],[Marital_Status]]="Absurd",K2+L2+1,marketing_campaign[[#This Row],[Marital_Status]]="Widow",K2+L2+1)} -> 1 | H2: {=_xlfn.IFS(marketing_campaign[[#This Row],[Family_size]]=1,"Family_with_one_child",marketing_campaign[[#This Row],[Family_size]]>1,"Family_with_more_children")} -> Family_with_one_child | I2: 58138 | J2: =IF(marketing_campaign[[#This Row],[Income]]>=Sheet21!B52,"high_income","low_income") -> low_income | K2: 0 | L2: 0 | M2: 41156 | N2: 58 | O2: {=_xlfn.IFS(AND(marketing_campaign[[#This Row],[Recency]]>=0,marketing_campaign[[#This Row],[Recency]]<=14),"Early Recency",AND(marketing_campaign[[#This Row],[Recency]]>=15,marketing_campaign[[#This Row],[Recency]]<=31),"Mid-Recency",marketing_campaign[[#This Row],[Recency]]>=32,"high Recency")} -> high Recency | P2: 635 | Q2: 88 | R2: 546 | S2: 172 | T2: 88 | U2: 88 | V2: =marketing_campaign[[#This Row],[MntGoldProds]]+marketing_campaign[[#This Row],[MntSweetProducts]]+marketing_campaign[[#This Row],[MntFishProducts]]+marketing_campaign[[#This Row],[MntMeatProducts]]+marketing_campaign[[#This Row],[MntFruits]]+marketing_campaign[[#This Row],[MntWines]] -> 1617 | W2: 3 | X2: 8 | Y2: 10 | Z2: 4 | AA2: =W2+X2+Y2+Z2 -> 25 | AB2: {=_xlfn.IFS(AND(AA2>=0,AA2<=15),"low purchase",AND(AA2>=16,AA2<=30),"mid purchase",AA2>=31,"high purchase")} -> mid purchase | AC2: 7 | AD2: =IF(marketing_campaign[[#This Row],[NumWebVisitsMonth]]>=5.3,"higher_webvists","lower_webvisits") -> higher_webvists | AE2: 0 | AF2: 0 | AG2: 0 | AH2: 0 | AI2: 0 | AJ2: 0 | AK2: 3 | AL2: 11 | AM2: 1 | AN2: =marketing_campaign[[#This Row],[AcceptedCmp2]]+marketing_campaign[[#This Row],[AcceptedCmp1]]+marketing_campaign[[#This Row],[AcceptedCmp5]]+marketing_campaign[[#This Row],[AcceptedCmp4]]+marketing_campaign[[#This Row],[AcceptedCmp3]]+marketing_campaign[[#This Row],[Response]] -> 1 | AO2: {=_xlfn.IFS(marketing_campaign[[#This Row],[CampaignAccepted]]=0,"low response",marketing_campaign[[#This Row],[CampaignAccepted]]=1,"1 / 5 response accepted",marketing_campaign[[#This Row],[CampaignAccepted]]=2,"2/5 campaign accepted",marketing_campaign[[#This Row],[CampaignAccepted]]=3,"3/5 campaign accepted",marketing_campaign[[#This Row],[CampaignAccepted]]=4,"4/5 campaign accepted",marketing_campaign[[#This Row],[CampaignAccepted]]=5,"high campaign response")} -> 1 / 5 response accepted
A3: 2174 | B3: 1954 | C3: =YEAR(TODAY())-B3 -> 72 | D3: {=_xlfn.IFS(AND(marketing_campaign[[#This Row],[Age]]>=30,marketing_campaign[[#This Row],[Age]]<=45),"30-45 Youth",AND(marketing_campaign[[#This Row],[Age]]>=46,marketing_campaign[[#This Row],[Age]]<=61),"46-61 Old",AND(marketing_campaign[[#This Row],[Age]]>=62,marketing_campaign[[#This Row],[Age]]<=77),"62-77 Snr Citizen",AND(marketing_campaign[[#This Row],[Age]]>=78,marketing_campaign[[#This Row],[Age]]<=133),"78-133 Elder")} -> 62-77 Snr Citizen | E3: Graduation | F3: Single | G3: {=_xlfn.IFS(marketing_campaign[[#This Row],[Marital_Status]]="Single",K3+L3+1,marketing_campaign[[#This Row],[Marital_Status]]="Together",K3+L3+2,marketing_campaign[[#This Row],[Marital_Status]]="Alone",K3+L3+1,marketing_campaign[[#This Row],[Marital_Status]]="Married",K3+L3+2,marketing_campaign[[#This Row],[Marital_Status]]="Divorced",K3+L3+1,marketing_campaign[[#This Row],[Marital_Status]]="YOLO",K3+L3+1,marketing_campaign[[#This Row],[Marital_Status]]="Absurd",K3+L3+1,marketing_campaign[[#This Row],[Marital_Status]]="Widow",K3+L3+1)} -> 3 | H3: {=_xlfn.IFS(marketing_campaign[[#This Row],[Family_size]]=1,"Family_with_one_child",marketing_campaign[[#This Row],[Family_size]]>1,"Family_with_more_children")} -> Family_with_more_children | I3: 46344 | J3: =IF(marketing_campaign[[#This Row],[Income]]>=Sheet21!B53,"high_income","low_income") -> high_income | K3: 1 | L3: 1 | M3: 41706 | N3: 38 | O3: {=_xlfn.IFS(AND(marketing_campaign[[#This Row],[Recency]]>=0,marketing_campaign[[#This Row],[Recency]]<=14),"Early Recency",AND(marketing_campaign[[#This Row],[Recency]]>=15,marketing_campaign[[#This Row],[Recency]]<=31),"Mid-Recency",marketing_campaign[[#This Row],[Recency]]>=32,"high Recency")} -> high Recency | P3: 11 | Q3: 1 | R3: 6 | S3: 2 | T3: 1 | U3: 6 | V3: =marketing_campaign[[#This Row],[MntGoldProds]]+marketing_campaign[[#This Row],[MntSweetProducts]]+marketing_campaign[[#This Row],[MntFishProducts]]+marketing_campaign[[#This Row],[MntMeatProducts]]+marketing_campaign[[#This Row],[MntFruits]]+marketing_campaign[[#This Row],[MntWines]] -> 27 | W3: 2 | X3: 1 | Y3: 1 | Z3: 2 | AA3: =W3+X3+Y3+Z3 -> 6 | AB3: {=_xlfn.IFS(AND(AA3>=0,AA3<=15),"low purchase",AND(AA3>=16,AA3<=30),"mid purchase",AA3>=31,"high purchase")} -> low purchase | AC3: 5 | AD3: =IF(marketing_campaign[[#This Row],[NumWebVisitsMonth]]>=5.3,"higher_webvists","lower_webvisits") -> lower_webvisits | AE3: 0 | AF3: 0 | AG3: 0 | AH3: 0 | AI3: 0 | AJ3: 0 | AK3: 3 | AL3: 11 | AM3: 0 | AN3: =marketing_campaign[[#This Row],[AcceptedCmp2]]+marketing_campaign[[#This Row],[AcceptedCmp1]]+marketing_campaign[[#This Row],[AcceptedCmp5]]+marketing_campaign[[#This Row],[AcceptedCmp4]]+marketing_campaign[[#This Row],[AcceptedCmp3]]+marketing_campaign[[#This Row],[Response]] -> 0 | AO3: {=_xlfn.IFS(marketing_campaign[[#This Row],[CampaignAccepted]]=0,"low response",marketing_campaign[[#This Row],[CampaignAccepted]]=1,"1 / 5 response accepted",marketing_campaign[[#This Row],[CampaignAccepted]]=2,"2/5 campaign accepted",marketing_campaign[[#This Row],[CampaignAccepted]]=3,"3/5 campaign accepted",marketing_campaign[[#This Row],[CampaignAccepted]]=4,"4/5 campaign accepted",marketing_campaign[[#This Row],[CampaignAccepted]]=5,"high campaign response")} -> low response
A4: 4141 | B4: 1965 | C4: =YEAR(TODAY())-B4 -> 61 | D4: {=_xlfn.IFS(AND(marketing_campaign[[#This Row],[Age]]>=30,marketing_campaign[[#This Row],[Age]]<=45),"30-45 Youth",AND(marketing_campaign[[#This Row],[Age]]>=46,marketing_campaign[[#This Row],[Age]]<=61),"46-61 Old",AND(marketing_campaign[[#This Row],[Age]]>=62,marketing_campaign[[#This Row],[Age]]<=77),"62-77 Snr Citizen",AND(marketing_campaign[[#This Row],[Age]]>=78,marketing_campaign[[#This Row],[Age]]<=133),"78-133 Elder")} -> 46-61 Old | E4: Graduation | F4: Together | G4: {=_xlfn.IFS(marketing_campaign[[#This Row],[Marital_Status]]="Single",K4+L4+1,marketing_campaign[[#This Row],[Marital_Status]]="Together",K4+L4+2,marketing_campaign[[#This Row],[Marital_Status]]="Alone",K4+L4+1,marketing_campaign[[#This Row],[Marital_Status]]="Married",K4+L4+2,marketing_campaign[[#This Row],[Marital_Status]]="Divorced",K4+L4+1,marketing_campaign[[#This Row],[Marital_Status]]="YOLO",K4+L4+1,marketing_campaign[[#This Row],[Marital_Status]]="Absurd",K4+L4+1,marketing_campaign[[#This Row],[Marital_Status]]="Widow",K4+L4+1)} -> 2 | H4: {=_xlfn.IFS(marketing_campaign[[#This Row],[Family_size]]=1,"Family_with_one_child",marketing_campaign[[#This Row],[Family_size]]>1,"Family_with_more_children")} -> Family_with_more_children | I4: 71613 | J4: =IF(marketing_campaign[[#This Row],[Income]]>=Sheet21!B54,"high_income","low_income") -> high_income | K4: 0 | L4: 0 | M4: 41507 | N4: 26 | O4: {=_xlfn.IFS(AND(marketing_campaign[[#This Row],[Recency]]>=0,marketing_campaign[[#This Row],[Recency]]<=14),"Early Recency",AND(marketing_campaign[[#This Row],[Recency]]>=15,marketing_campaign[[#This Row],[Recency]]<=31),"Mid-Recency",marketing_campaign[[#This Row],[Recency]]>=32,"high Recency")} -> Mid-Recency | P4: 426 | Q4: 49 | R4: 127 | S4: 111 | T4: 21 | U4: 42 | V4: =marketing_campaign[[#This Row],[MntGoldProds]]+marketing_campaign[[#This Row],[MntSweetProducts]]+marketing_campaign[[#This Row],[MntFishProducts]]+marketing_campaign[[#This Row],[MntMeatProducts]]+marketing_campaign[[#This Row],[MntFruits]]+marketing_campaign[[#This Row],[MntWines]] -> 776 | W4: 1 | X4: 8 | Y4: 2 | Z4: 10 | AA4: =W4+X4+Y4+Z4 -> 21 | AB4: {=_xlfn.IFS(AND(AA4>=0,AA4<=15),"low purchase",AND(AA4>=16,AA4<=30),"mid purchase",AA4>=31,"high purchase")} -> mid purchase | AC4: 4 | AD4: =IF(marketing_campaign[[#This Row],[NumWebVisitsMonth]]>=5.3,"higher_webvists","lower_webvisits") -> lower_webvisits | AE4: 0 | AF4: 0 | AG4: 0 | AH4: 0 | AI4: 0 | AJ4: 0 | AK4: 3 | AL4: 11 | AM4: 0 | AN4: =marketing_campaign[[#This Row],[AcceptedCmp2]]+marketing_campaign[[#This Row],[AcceptedCmp1]]+marketing_campaign[[#This Row],[AcceptedCmp5]]+marketing_campaign[[#This Row],[AcceptedCmp4]]+marketing_campaign[[#This Row],[AcceptedCmp3]]+marketing_campaign[[#This Row],[Response]] -> 0 | AO4: {=_xlfn.IFS(marketing_campaign[[#This Row],[CampaignAccepted]]=0,"low response",marketing_campaign[[#This Row],[CampaignAccepted]]=1,"1 / 5 response accepted",marketing_campaign[[#This Row],[CampaignAccepted]]=2,"2/5 campaign accepted",marketing_campaign[[#This Row],[CampaignAccepted]]=3,"3/5 campaign accepted",marketing_campaign[[#This Row],[CampaignAccepted]]=4,"4/5 campaign accepted",marketing_campaign[[#This Row],[CampaignAccepted]]=5,"high campaign response")} -> low response
A5: 6182 | B5: 1984 | C5: =YEAR(TODAY())-B5 -> 42 | D5: {=_xlfn.IFS(AND(marketing_campaign[[#This Row],[Age]]>=30,marketing_campaign[[#This Row],[Age]]<=45),"30-45 Youth",AND(marketing_campaign[[#This Row],[Age]]>=46,marketing_campaign[[#This Row],[Age]]<=61),"46-61 Old",AND(marketing_campaign[[#This Row],[Age]]>=62,marketing_campaign[[#This Row],[Age]]<=77),"62-77 Snr Citizen",AND(marketing_campaign[[#This Row],[Age]]>=78,marketing_campaign[[#This Row],[Age]]<=133),"78-133 Elder")} -> 30-45 Youth | E5: Graduation | F5: Together | G5: {=_xlfn.IFS(marketing_campaign[[#This Row],[Marital_Status]]="Single",K5+L5+1,marketing_campaign[[#This Row],[Marital_Status]]="Together",K5+L5+2,marketing_campaign[[#This Row],[Marital_Status]]="Alone",K5+L5+1,marketing_campaign[[#This Row],[Marital_Status]]="Married",K5+L5+2,marketing_campaign[[#This Row],[Marital_Status]]="Divorced",K5+L5+1,marketing_campaign[[#This Row],[Marital_Status]]="YOLO",K5+L5+1,marketing_campaign[[#This Row],[Marital_Status]]="Absurd",K5+L5+1,marketing_campaign[[#This Row],[Marital_Status]]="Widow",K5+L5+1)} -> 3 | H5: {=_xlfn.IFS(marketing_campaign[[#This Row],[Family_size]]=1,"Family_with_one_child",marketing_campaign[[#This Row],[Family_size]]>1,"Family_with_more_children")} -> Family_with_more_children | I5: 26646 | J5: =IF(marketing_campaign[[#This Row],[Income]]>=Sheet21!B55,"high_income","low_income") -> high_income | K5: 1 | L5: 0 | M5: 41680 | N5: 26 | O5: {=_xlfn.IFS(AND(marketing_campaign[[#This Row],[Recency]]>=0,marketing_campaign[[#This Row],[Recency]]<=14),"Early Recency",AND(marketing_campaign[[#This Row],[Recency]]>=15,marketing_campaign[[#This Row],[Recency]]<=31),"Mid-Recency",marketing_campaign[[#This Row],[Recency]]>=32,"high Recency")} -> Mid-Recency | P5: 11 | Q5: 4 | R5: 20 | S5: 10 | T5: 3 | U5: 5 | V5: =marketing_campaign[[#This Row],[MntGoldProds]]+marketing_campaign[[#This Row],[MntSweetProducts]]+marketing_campaign[[#This Row],[MntFishProducts]]+marketing_campaign[[#This Row],[MntMeatProducts]]+marketing_campaign[[#This Row],[MntFruits]]+marketing_campaign[[#This Row],[MntWines]] -> 53 | W5: 2 | X5: 2 | Y5: 0 | Z5: 4 | AA5: =W5+X5+Y5+Z5 -> 8 | AB5: {=_xlfn.IFS(AND(AA5>=0,AA5<=15),"low purchase",AND(AA5>=16,AA5<=30),"mid purchase",AA5>=31,"high purchase")} -> low purchase | AC5: 6 | AD5: =IF(marketing_campaign[[#This Row],[NumWebVisitsMonth]]>=5.3,"higher_webvists","lower_webvisits") -> higher_webvists | AE5: 0 | AF5: 0 | AG5: 0 | AH5: 0 | AI5: 0 | AJ5: 0 | AK5: 3 | AL5: 11 | AM5: 0 | AN5: =marketing_campaign[[#This Row],[AcceptedCmp2]]+marketing_campaign[[#This Row],[AcceptedCmp1]]+marketing_campaign[[#This Row],[AcceptedCmp5]]+marketing_campaign[[#This Row],[AcceptedCmp4]]+marketing_campaign[[#This Row],[AcceptedCmp3]]+marketing_campaign[[#This Row],[Response]] -> 0 | AO5: {=_xlfn.IFS(marketing_campaign[[#This Row],[CampaignAccepted]]=0,"low response",marketing_campaign[[#This Row],[CampaignAccepted]]=1,"1 / 5 response accepted",marketing_campaign[[#This Row],[CampaignAccepted]]=2,"2/5 campaign accepted",marketing_campaign[[#This Row],[CampaignAccepted]]=3,"3/5 campaign accepted",marketing_campaign[[#This Row],[CampaignAccepted]]=4,"4/5 campaign accepted",marketing_campaign[[#This Row],[CampaignAccepted]]=5,"high campaign response")} -> low response
A6: 5324 | B6: 1981 | C6: =YEAR(TODAY())-B6 -> 45 | D6: {=_xlfn.IFS(AND(marketing_campaign[[#This Row],[Age]]>=30,marketing_campaign[[#This Row],[Age]]<=45),"30-45 Youth",AND(marketing_campaign[[#This Row],[Age]]>=46,marketing_campaign[[#This Row],[Age]]<=61),"46-61 Old",AND(marketing_campaign[[#This Row],[Age]]>=62,marketing_campaign[[#This Row],[Age]]<=77),"62-77 Snr Citizen",AND(marketing_campaign[[#This Row],[Age]]>=78,marketing_campaign[[#This Row],[Age]]<=133),"78-133 Elder")} -> 30-45 Youth | E6: PhD | F6: Married | G6: {=_xlfn.IFS(marketing_campaign[[#This Row],[Marital_Status]]="Single",K6+L6+1,marketing_campaign[[#This Row],[Marital_Status]]="Together",K6+L6+2,marketing_campaign[[#This Row],[Marital_Status]]="Alone",K6+L6+1,marketing_campaign[[#This Row],[Marital_Status]]="Married",K6+L6+2,marketing_campaign[[#This Row],[Marital_Status]]="Divorced",K6+L6+1,marketing_campaign[[#This Row],[Marital_Status]]="YOLO",K6+L6+1,marketing_campaign[[#This Row],[Marital_Status]]="Absurd",K6+L6+1,marketing_campaign[[#This Row],[Marital_Status]]="Widow",K6+L6+1)} -> 3 | H6: {=_xlfn.IFS(marketing_campaign[[#This Row],[Family_size]]=1,"Family_with_one_child",marketing_campaign[[#This Row],[Family_size]]>1,"Family_with_more_children")} -> Family_with_more_children | I6: 58293 | J6: =IF(marketing_campaign[[#This Row],[Income]]>=Sheet21!B56,"high_income","low_income") -> high_income | K6: 1 | L6: 0 | M6: 41658 | N6: 94 | O6: {=_xlfn.IFS(AND(marketing_campaign[[#This Row],[Recency]]>=0,marketing_campaign[[#This Row],[Recency]]<=14),"Early Recency",AND(marketing_campaign[[#This Row],[Recency]]>=15,marketing_campaign[[#This Row],[Recency]]<=31),"Mid-Recency",marketing_campaign[[#This Row],[Recency]]>=32,"high Recency")} -> high Recency | P6: 173 | Q6: 43 | R6: 118 | S6: 46 | T6: 27 | U6: 15 | V6: =marketing_campaign[[#This Row],[MntGoldProds]]+marketing_campaign[[#This Row],[MntSweetProducts]]+marketing_campaign[[#This Row],[MntFishProducts]]+marketing_campaign[[#This Row],[MntMeatProducts]]+marketing_campaign[[#This Row],[MntFruits]]+marketing_campaign[[#This Row],[MntWines]] -> 422 | W6: 5 | X6: 5 | Y6: 3 | Z6: 6 | AA6: =W6+X6+Y6+Z6 -> 19 | AB6: {=_xlfn.IFS(AND(AA6>=0,AA6<=15),"low purchase",AND(AA6>=16,AA6<=30),"mid purchase",AA6>=31,"high purchase")} -> mid purchase | AC6: 5 | AD6: =IF(marketing_campaign[[#This Row],[NumWebVisitsMonth]]>=5.3,"higher_webvists","lower_webvisits") -> lower_webvisits | AE6: 0 | AF6: 0 | AG6: 0 | AH6: 0 | AI6: 0 | AJ6: 0 | AK6: 3 | AL6: 11 | AM6: 0 | AN6: =marketing_campaign[[#This Row],[AcceptedCmp2]]+marketing_campaign[[#This Row],[AcceptedCmp1]]+marketing_campaign[[#This Row],[AcceptedCmp5]]+marketing_campaign[[#This Row],[AcceptedCmp4]]+marketing_campaign[[#This Row],[AcceptedCmp3]]+marketing_campaign[[#This Row],[Response]] -> 0 | AO6: {=_xlfn.IFS(marketing_campaign[[#This Row],[CampaignAccepted]]=0,"low response",marketing_campaign[[#This Row],[CampaignAccepted]]=1,"1 / 5 response accepted",marketing_campaign[[#This Row],[CampaignAccepted]]=2,"2/5 campaign accepted",marketing_campaign[[#This Row],[CampaignAccepted]]=3,"3/5 campaign accepted",marketing_campaign[[#This Row],[CampaignAccepted]]=4,"4/5 campaign accepted",marketing_campaign[[#This Row],[CampaignAccepted]]=5,"high campaign response")} -> low response
A7: 7446 | B7: 1967 | C7: =YEAR(TODAY())-B7 -> 59 | D7: {=_xlfn.IFS(AND(marketing_campaign[[#This Row],[Age]]>=30,marketing_campaign[[#This Row],[Age]]<=45),"30-45 Youth",AND(marketing_campaign[[#This Row],[Age]]>=46,marketing_campaign[[#This Row],[Age]]<=61),"46-61 Old",AND(marketing_campaign[[#This Row],[Age]]>=62,marketing_campaign[[#This Row],[Age]]<=77),"62-77 Snr Citizen",AND(marketing_campaign[[#This Row],[Age]]>=78,marketing_campaign[[#This Row],[Age]]<=133),"78-133 Elder")} -> 46-61 Old | E7: Master | F7: Together | G7: {=_xlfn.IFS(marketing_campaign[[#This Row],[Marital_Status]]="Single",K7+L7+1,marketing_campaign[[#This Row],[Marital_Status]]="Together",K7+L7+2,marketing_campaign[[#This Row],[Marital_Status]]="Alone",K7+L7+1,marketing_campaign[[#This Row],[Marital_Status]]="Married",K7+L7+2,marketing_campaign[[#This Row],[Marital_Status]]="Divorced",K7+L7+1,marketing_campaign[[#This Row],[Marital_Status]]="YOLO",K7+L7+1,marketing_campaign[[#This Row],[Marital_Status]]="Absurd",K7+L7+1,marketing_campaign[[#This Row],[Marital_Status]]="Widow",K7+L7+1)} -> 3 | H7: {=_xlfn.IFS(marketing_campaign[[#This Row],[Family_size]]=1,"Family_with_one_child",marketing_campaign[[#This Row],[Family_size]]>1,"Family_with_more_children")} -> Family_with_more_children | I7: 62513 | J7: =IF(marketing_campaign[[#This Row],[Income]]>=Sheet21!B57,"high_income","low_income") -> high_income | K7: 0 | L7: 1 | M7: 41526 | N7: 16 | O7: {=_xlfn.IFS(AND(marketing_campaign[[#This Row],[Recency]]>=0,marketing_campaign[[#This Row],[Recency]]<=14),"Early Recency",AND(marketing_campaign[[#This Row],[Recency]]>=15,marketing_campaign[[#This Row],[Recency]]<=31),"Mid-Recency",marketing_campaign[[#This Row],[Recency]]>=32,"high Recency")} -> Mid-Recency | P7: 520 | Q7: 42 | R7: 98 | S7: 0 | T7: 42 | U7: 14 | V7: =marketing_campaign[[#This Row],[MntGoldProds]]+marketing_campaign[[#This Row],[MntSweetProducts]]+marketing_campaign[[#This Row],[MntFishProducts]]+marketing_campaign[[#This Row],[MntMeatProducts]]+marketing_campaign[[#This Row],[MntFruits]]+marketing_campaign[[#This Row],[MntWines]] -> 716 | W7: 2 | X7: 6 | Y7: 4 | Z7: 10 | AA7: =W7+X7+Y7+Z7 -> 22 | AB7: {=_xlfn.IFS(AND(AA7>=0,AA7<=15),"low purchase",AND(AA7>=16,AA7<=30),"mid purchase",AA7>=31,"high purchase")} -> mid purchase | AC7: 6 | AD7: =IF(marketing_campaign[[#This Row],[NumWebVisitsMonth]]>=5.3,"higher_webvists","lower_webvisits") -> higher_webvists | AE7: 0 | AF7: 0 | AG7: 0 | AH7: 0 | AI7: 0 | AJ7: 0 | AK7: 3 | AL7: 11 | AM7: 0 | AN7: =marketing_campaign[[#This Row],[AcceptedCmp2]]+marketing_campaign[[#This Row],[AcceptedCmp1]]+marketing_campaign[[#This Row],[AcceptedCmp5]]+marketing_campaign[[#This Row],[AcceptedCmp4]]+marketing_campaign[[#This Row],[AcceptedCmp3]]+marketing_campaign[[#This Row],[Response]] -> 0 | AO7: {=_xlfn.IFS(marketing_campaign[[#This Row],[CampaignAccepted]]=0,"low response",marketing_campaign[[#This Row],[CampaignAccepted]]=1,"1 / 5 response accepted",marketing_campaign[[#This Row],[CampaignAccepted]]=2,"2/5 campaign accepted",marketing_campaign[[#This Row],[CampaignAccepted]]=3,"3/5 campaign accepted",marketing_campaign[[#This Row],[CampaignAccepted]]=4,"4/5 campaign accepted",marketing_campaign[[#This Row],[CampaignAccepted]]=5,"high campaign response")} -> low response
A8: 965 | B8: 1971 | C8: =YEAR(TODAY())-B8 -> 55 | D8: {=_xlfn.IFS(AND(marketing_campaign[[#This Row],[Age]]>=30,marketing_campaign[[#This Row],[Age]]<=45),"30-45 Youth",AND(marketing_campaign[[#This Row],[Age]]>=46,marketing_campaign[[#This Row],[Age]]<=61),"46-61 Old",AND(marketing_campaign[[#This Row],[Age]]>=62,marketing_campaign[[#This Row],[Age]]<=77),"62-77 Snr Citizen",AND(marketing_campaign[[#This Row],[Age]]>=78,marketing_campaign[[#This Row],[Age]]<=133),"78-133 Elder")} -> 46-61 Old | E8: Graduation | F8: Divorced | G8: {=_xlfn.IFS(marketing_campaign[[#This Row],[Marital_Status]]="Single",K8+L8+1,marketing_campaign[[#This Row],[Marital_Status]]="Together",K8+L8+2,marketing_campaign[[#This Row],[Marital_Status]]="Alone",K8+L8+1,marketing_campaign[[#This Row],[Marital_Status]]="Married",K8+L8+2,marketing_campaign[[#This Row],[Marital_Status]]="Divorced",K8+L8+1,marketing_campaign[[#This Row],[Marital_Status]]="YOLO",K8+L8+1,marketing_campaign[[#This Row],[Marital_Status]]="Absurd",K8+L8+1,marketing_campaign[[#This Row],[Marital_Status]]="Widow",K8+L8+1)} -> 2 | H8: {=_xlfn.IFS(marketing_campaign[[#This Row],[Family_size]]=1,"Family_with_one_child",marketing_campaign[[#This Row],[Family_size]]>1,"Family_with_more_children")} -> Family_with_more_children | I8: 55635 | J8: =IF(marketing_campaign[[#This Row],[Income]]>=Sheet21!B58,"high_income","low_income") -> high_income | K8: 0 | L8: 1 | M8: 41226 | N8: 34 | O8: {=_xlfn.IFS(AND(marketing_campaign[[#This Row],[Recency]]>=0,marketing_campaign[[#This Row],[Recency]]<=14),"Early Recency",AND(marketing_campaign[[#This Row],[Recency]]>=15,marketing_campaign[[#This Row],[Recency]]<=31),"Mid-Recency",marketing_campaign[[#This Row],[Recency]]>=32,"high Recency")} -> high Recency | P8: 235 | Q8: 65 | R8: 164 | S8: 50 | T8: 49 | U8: 27 | V8: =marketing_campaign[[#This Row],[MntGoldProds]]+marketing_campaign[[#This Row],[MntSweetProducts]]+marketing_campaign[[#This Row],[MntFishProducts]]+marketing_campaign[[#This Row],[MntMeatProducts]]+marketing_campaign[[#This Row],[MntFruits]]+marketing_campaign[[#This Row],[MntWines]] -> 590 | W8: 4 | X8: 7 | Y8: 3 | Z8: 7 | AA8: =W8+X8+Y8+Z8 -> 21 | AB8: {=_xlfn.IFS(AND(AA8>=0,AA8<=15),"low purchase",AND(AA8>=16,AA8<=30),"mid purchase",AA8>=31,"high purchase")} -> mid purchase | AC8: 6 | AD8: =IF(marketing_campaign[[#This Row],[NumWebVisitsMonth]]>=5.3,"higher_webvists","lower_webvisits") -> higher_webvists | AE8: 0 | AF8: 0 | AG8: 0 | AH8: 0 | AI8: 0 | AJ8: 0 | AK8: 3 | AL8: 11 | AM8: 0 | AN8: =marketing_campaign[[#This Row],[AcceptedCmp2]]+marketing_campaign[[#This Row],[AcceptedCmp1]]+marketing_campaign[[#This Row],[AcceptedCmp5]]+marketing_campaign[[#This Row],[AcceptedCmp4]]+marketing_campaign[[#This Row],[AcceptedCmp3]]+marketing_campaign[[#This Row],[Response]] -> 0 | AO8: {=_xlfn.IFS(marketing_campaign[[#This Row],[CampaignAccepted]]=0,"low response",marketing_campaign[[#This Row],[CampaignAccepted]]=1,"1 / 5 response accepted",marketing_campaign[[#This Row],[CampaignAccepted]]=2,"2/5 campaign accepted",marketing_campaign[[#This Row],[CampaignAccepted]]=3,"3/5 campaign accepted",marketing_campaign[[#This Row],[CampaignAccepted]]=4,"4/5 campaign accepted",marketing_campaign[[#This Row],[CampaignAccepted]]=5,"high campaign response")} -> low response
A9: 6177 | B9: 1985 | C9: =YEAR(TODAY())-B9 -> 41 | D9: {=_xlfn.IFS(AND(marketing_campaign[[#This Row],[Age]]>=30,marketing_campaign[[#This Row],[Age]]<=45),"30-45 Youth",AND(marketing_campaign[[#This Row],[Age]]>=46,marketing_campaign[[#This Row],[Age]]<=61),"46-61 Old",AND(marketing_campaign[[#This Row],[Age]]>=62,marketing_campaign[[#This Row],[Age]]<=77),"62-77 Snr Citizen",AND(marketing_campaign[[#This Row],[Age]]>=78,marketing_campaign[[#This Row],[Age]]<=133),"78-133 Elder")} -> 30-45 Youth | E9: PhD | F9: Married | G9: {=_xlfn.IFS(marketing_campaign[[#This Row],[Marital_Status]]="Single",K9+L9+1,marketing_campaign[[#This Row],[Marital_Status]]="Together",K9+L9+2,marketing_campaign[[#This Row],[Marital_Status]]="Alone",K9+L9+1,marketing_campaign[[#This Row],[Marital_Status]]="Married",K9+L9+2,marketing_campaign[[#This Row],[Marital_Status]]="Divorced",K9+L9+1,marketing_campaign[[#This Row],[Marital_Status]]="YOLO",K9+L9+1,marketing_campaign[[#This Row],[Marital_Status]]="Absurd",K9+L9+1,marketing_campaign[[#This Row],[Marital_Status]]="Widow",K9+L9+1)} -> 3 | H9: {=_xlfn.IFS(marketing_campaign[[#This Row],[Family_size]]=1,"Family_with_one_child",marketing_campaign[[#This Row],[Family_size]]>1,"Family_with_more_children")} -> Family_with_more_children | I9: 33454 | J9: =IF(marketing_campaign[[#This Row],[Income]]>=Sheet21!B59,"high_income","low_income") -> high_income | K9: 1 | L9: 0 | M9: 41402 | N9: 32 | O9: {=_xlfn.IFS(AND(marketing_campaign[[#This Row],[Recency]]>=0,marketing_campaign[[#This Row],[Recency]]<=14),"Early Recency",AND(marketing_campaign[[#This Row],[Recency]]>=15,marketing_campaign[[#This Row],[Recency]]<=31),"Mid-Recency",marketing_campaign[[#This Row],[Recency]]>=32,"high Recency")} -> high Recency | P9: 76 | Q9: 10 | R9: 56 | S9: 3 | T9: 1 | U9: 23 | V9: =marketing_campaign[[#This Row],[MntGoldProds]]+marketing_campaign[[#This Row],[MntSweetProducts]]+marketing_campaign[[#This Row],[MntFishProducts]]+marketing_campaign[[#This Row],[MntMeatProducts]]+marketing_campaign[[#This Row],[MntFruits]]+marketing_campaign[[#This Row],[MntWines]] -> 169 | W9: 2 | X9: 4 | Y9: 0 | Z9: 4 | AA9: =W9+X9+Y9+Z9 -> 10 | AB9: {=_xlfn.IFS(AND(AA9>=0,AA9<=15),"low purchase",AND(AA9>=16,AA9<=30),"mid purchase",AA9>=31,"high purchase")} -> low purchase | AC9: 8 | AD9: =IF(marketing_campaign[[#This Row],[NumWebVisitsMonth]]>=5.3,"higher_webvists","lower_webvisits") -> higher_webvists | AE9: 0 | AF9: 0 | AG9: 0 | AH9: 0 | AI9: 0 | AJ9: 0 | AK9: 3 | AL9: 11 | AM9: 0 | AN9: =marketing_campaign[[#This Row],[AcceptedCmp2]]+marketing_campaign[[#This Row],[AcceptedCmp1]]+marketing_campaign[[#This Row],[AcceptedCmp5]]+marketing_campaign[[#This Row],[AcceptedCmp4]]+marketing_campaign[[#This Row],[AcceptedCmp3]]+marketing_campaign[[#This Row],[Response]] -> 0 | AO9: {=_xlfn.IFS(marketing_campaign[[#This Row],[CampaignAccepted]]=0,"low response",marketing_campaign[[#This Row],[CampaignAccepted]]=1,"1 / 5 response accepted",marketing_campaign[[#This Row],[CampaignAccepted]]=2,"2/5 campaign accepted",marketing_campaign[[#This Row],[CampaignAccepted]]=3,"3/5 campaign accepted",marketing_campaign[[#This Row],[CampaignAccepted]]=4,"4/5 campaign accepted",marketing_campaign[[#This Row],[CampaignAccepted]]=5,"high campaign response")} -> low response
A10: 4855 | B10: 1974 | C10: =YEAR(TODAY())-B10 -> 52 | D10: {=_xlfn.IFS(AND(marketing_campaign[[#This Row],[Age]]>=30,marketing_campaign[[#This Row],[Age]]<=45),"30-45 Youth",AND(marketing_campaign[[#This Row],[Age]]>=46,marketing_campaign[[#This Row],[Age]]<=61),"46-61 Old",AND(marketing_campaign[[#This Row],[Age]]>=62,marketing_campaign[[#This Row],[Age]]<=77),"62-77 Snr Citizen",AND(marketing_campaign[[#This Row],[Age]]>=78,marketing_campaign[[#This Row],[Age]]<=133),"78-133 Elder")} -> 46-61 Old | E10: PhD | F10: Together | G10: {=_xlfn.IFS(marketing_campaign[[#This Row],[Marital_Status]]="Single",K10+L10+1,marketing_campaign[[#This Row],[Marital_Status]]="Together",K10+L10+2,marketing_campaign[[#This Row],[Marital_Status]]="Alone",K10+L10+1,marketing_campaign[[#This Row],[Marital_Status]]="Married",K10+L10+2,marketing_campaign[[#This Row],[Marital_Status]]="Divorced",K10+L10+1,marketing_campaign[[#This Row],[Marital_Status]]="YOLO",K10+L10+1,marketing_campaign[[#This Row],[Marital_Status]]="Absurd",K10+L10+1,marketing_campaign[[#This Row],[Marital_Status]]="Widow",K10+L10+1)} -> 3 | H10: {=_xlfn.IFS(marketing_campaign[[#This Row],[Family_size]]=1,"Family_with_one_child",marketing_campaign[[#This Row],[Family_size]]>1,"Family_with_more_children")} -> Family_with_more_children | I10: 30351 | J10: =IF(marketing_campaign[[#This Row],[Income]]>=Sheet21!B60,"high_income","low_income") -> high_income | K10: 1 | L10: 0 | M10: 41431 | N10: 19 | O10: {=_xlfn.IFS(AND(marketing_campaign[[#This Row],[Recency]]>=0,marketing_campaign[[#This Row],[Recency]]<=14),"Early Recency",AND(marketing_campaign[[#This Row],[Recency]]>=15,marketing_campaign[[#This Row],[Recency]]<=31),"Mid-Recency",marketing_campaign[[#This Row],[Recency]]>=32,"high Recency")} -> Mid-Recency | P10: 14 | Q10: 0 | R10: 24 | S10: 3 | T10: 3 | U10: 2 | V10: =marketing_campaign[[#This Row],[MntGoldProds]]+marketing_campaign[[#This Row],[MntSweetProducts]]+marketing_campaign[[#This Row],[MntFishProducts]]+marketing_campaign[[#This Row],[MntMeatProducts]]+marketing_campaign[[#This Row],[MntFruits]]+marketing_campaign[[#This Row],[MntWines]] -> 46 | W10: 1 | X10: 3 | Y10: 0 | Z10: 2 | AA10: =W10+X10+Y10+Z10 -> 6 | AB10: {=_xlfn.IFS(AND(AA10>=0,AA10<=15),"low purchase",AND(AA10>=16,AA10<=30),"mid purchase",AA10>=31,"high purchase")} -> low purchase | AC10: 9 | AD10: =IF(marketing_campaign[[#This Row],[NumWebVisitsMonth]]>=5.3,"higher_webvists","lower_webvisits") -> higher_webvists | AE10: 0 | AF10: 0 | AG10: 0 | AH10: 0 | AI10: 0 | AJ10: 0 | AK10: 3 | AL10: 11 | AM10: 1 | AN10: =marketing_campaign[[#This Row],[AcceptedCmp2]]+marketing_campaign[[#This Row],[AcceptedCmp1]]+marketing_campaign[[#This Row],[AcceptedCmp5]]+marketing_campaign[[#This Row],[AcceptedCmp4]]+marketing_campaign[[#This Row],[AcceptedCmp3]]+marketing_campaign[[#This Row],[Response]] -> 1 | AO10: {=_xlfn.IFS(marketing_campaign[[#This Row],[CampaignAccepted]]=0,"low response",marketing_campaign[[#This Row],[CampaignAccepted]]=1,"1 / 5 response accepted",marketing_campaign[[#This Row],[CampaignAccepted]]=2,"2/5 campaign accepted",marketing_campaign[[#This Row],[CampaignAccepted]]=3,"3/5 campaign accepted",marketing_campaign[[#This Row],[CampaignAccepted]]=4,"4/5 campaign accepted",marketing_campaign[[#This Row],[CampaignAccepted]]=5,"high campaign response")} -> 1 / 5 response accepted
A11: 5899 | B11: 1950 | C11: =YEAR(TODAY())-B11 -> 76 | D11: {=_xlfn.IFS(AND(marketing_campaign[[#This Row],[Age]]>=30,marketing_campaign[[#This Row],[Age]]<=45),"30-45 Youth",AND(marketing_campaign[[#This Row],[Age]]>=46,marketing_campaign[[#This Row],[Age]]<=61),"46-61 Old",AND(marketing_campaign[[#This Row],[Age]]>=62,marketing_campaign[[#This Row],[Age]]<=77),"62-77 Snr Citizen",AND(marketing_campaign[[#This Row],[Age]]>=78,marketing_campaign[[#This Row],[Age]]<=133),"78-133 Elder")} -> 62-77 Snr Citizen | E11: PhD | F11: Together | G11: {=_xlfn.IFS(marketing_campaign[[#This Row],[Marital_Status]]="Single",K11+L11+1,marketing_campaign[[#This Row],[Marital_Status]]="Together",K11+L11+2,marketing_campaign[[#This Row],[Marital_Status]]="Alone",K11+L11+1,marketing_campaign[[#This Row],[Marital_Status]]="Married",K11+L11+2,marketing_campaign[[#This Row],[Marital_Status]]="Divorced",K11+L11+1,marketing_campaign[[#This Row],[Marital_Status]]="YOLO",K11+L11+1,marketing_campaign[[#This Row],[Marital_Status]]="Absurd",K11+L11+1,marketing_campaign[[#This Row],[Marital_Status]]="Widow",K11+L11+1)} -> 4 | H11: {=_xlfn.IFS(marketing_campaign[[#This Row],[Family_size]]=1,"Family_with_one_child",marketing_campaign[[#This Row],[Family_size]]>1,"Family_with_more_children")} -> Family_with_more_children | I11: 5648 | J11: =IF(marketing_campaign[[#This Row],[Income]]>=Sheet21!B61,"high_income","low_income") -> high_income | K11: 1 | L11: 1 | M11: 41711 | N11: 68 | O11: {=_xlfn.IFS(AND(marketing_campaign[[#This Row],[Recency]]>=0,marketing_campaign[[#This Row],[Recency]]<=14),"Early Recency",AND(marketing_campaign[[#This Row],[Recency]]>=15,marketing_campaign[[#This Row],[Recency]]<=31),"Mid-Recency",marketing_campaign[[#This Row],[Recency]]>=32,"high Recency")} -> high Recency | P11: 28 | Q11: 0 | R11: 6 | S11: 1 | T11: 1 | U11: 13 | V11: =marketing_campaign[[#This Row],[MntGoldProds]]+marketing_campaign[[#This Row],[MntSweetProducts]]+marketing_campaign[[#This Row],[MntFishProducts]]+marketing_campaign[[#This Row],[MntMeatProducts]]+marketing_campaign[[#This Row],[MntFruits]]+marketing_campaign[[#This Row],[MntWines]] -> 49 | W11: 1 | X11: 1 | Y11: 0 | Z11: 0 | AA11: =W11+X11+Y11+Z11 -> 2 | AB11: {=_xlfn.IFS(AND(AA11>=0,AA11<=15),"low purchase",AND(AA11>=16,AA11<=30),"mid purchase",AA11>=31,"high purchase")} -> low purchase | AC11: 20 | AD11: =IF(marketing_campaign[[#This Row],[NumWebVisitsMonth]]>=5.3,"higher_webvists","lower_webvisits") -> higher_webvists | AE11: 1 | AF11: 0 | AG11: 0 | AH11: 0 | AI11: 0 | AJ11: 0 | AK11: 3 | AL11: 11 | AM11: 0 | AN11: =marketing_campaign[[#This Row],[AcceptedCmp2]]+marketing_campaign[[#This Row],[AcceptedCmp1]]+marketing_campaign[[#This Row],[AcceptedCmp5]]+marketing_campaign[[#This Row],[AcceptedCmp4]]+marketing_campaign[[#This Row],[AcceptedCmp3]]+marketing_campaign[[#This Row],[Response]] -> 1 | AO11: {=_xlfn.IFS(marketing_campaign[[#This Row],[CampaignAccepted]]=0,"low response",marketing_campaign[[#This Row],[CampaignAccepted]]=1,"1 / 5 response accepted",marketing_campaign[[#This Row],[CampaignAccepted]]=2,"2/5 campaign accepted",marketing_campaign[[#This Row],[CampaignAccepted]]=3,"3/5 campaign accepted",marketing_campaign[[#This Row],[CampaignAccepted]]=4,"4/5 campaign accepted",marketing_campaign[[#This Row],[CampaignAccepted]]=5,"high campaign response")} -> 1 / 5 response accepted
A12: 1994 | B12: 1983 | C12: =YEAR(TODAY())-B12 -> 43 | D12: {=_xlfn.IFS(AND(marketing_campaign[[#This Row],[Age]]>=30,marketing_campaign[[#This Row],[Age]]<=45),"30-45 Youth",AND(marketing_campaign[[#This Row],[Age]]>=46,marketing_campaign[[#This Row],[Age]]<=61),"46-61 Old",AND(marketing_campaign[[#This Row],[Age]]>=62,marketing_campaign[[#This Row],[Age]]<=77),"62-77 Snr Citizen",AND(marketing_campaign[[#This Row],[Age]]>=78,marketing_campaign[[#This Row],[Age]]<=133),"78-133 Elder")} -> 30-45 Youth | E12: Graduation | F12: Married | G12: {=_xlfn.IFS(marketing_campaign[[#This Row],[Marital_Status]]="Single",K12+L12+1,marketing_campaign[[#This Row],[Marital_Status]]="Together",K12+L12+2,marketing_campaign[[#This Row],[Marital_Status]]="Alone",K12+L12+1,marketing_campaign[[#This Row],[Marital_Status]]="Married",K12+L12+2,marketing_campaign[[#This Row],[Marital_Status]]="Divorced",K12+L12+1,marketing_campaign[[#This Row],[Marital_Status]]="YOLO",K12+L12+1,marketing_campaign[[#This Row],[Marital_Status]]="Absurd",K12+L12+1,marketing_campaign[[#This Row],[Marital_Status]]="Widow",K12+L12+1)} -> 3 | H12: {=_xlfn.IFS(marketing_campaign[[#This Row],[Family_size]]=1,"Family_with_one_child",marketing_campaign[[#This Row],[Family_size]]>1,"Family_with_more_children")} -> Family_with_more_children | I12: 51386 | J12: =IF(marketing_campaign[[#This Row],[Income]]>=Sheet21!B62,"high_income","low_income") -> high_income | K12: 1 | L12: 0 | M12: 41593 | N12: 11 | O12: {=_xlfn.IFS(AND(marketing_campaign[[#This Row],[Recency]]>=0,marketing_campaign[[#This Row],[Recency]]<=14),"Early Recency",AND(marketing_campaign[[#This Row],[Recency]]>=15,marketing_campaign[[#This Row],[Recency]]<=31),"Mid-Recency",marketing_campaign[[#This Row],[Recency]]>=32,"high Recency")} -> Early Recency | P12: 5 | Q12: 5 | R12: 6 | S12: 0 | T12: 2 | U12: 1 | V12: =marketing_campaign[[#This Row],[MntGoldProds]]+marketing_campaign[[#This Row],[MntSweetProducts]]+marketing_campaign[[#This Row],[MntFishProducts]]+marketing_campaign[[#This Row],[MntMeatProducts]]+marketing_campaign[[#This Row],[MntFruits]]+marketing_campaign[[#This Row],[MntWines]] -> 19 | W12: 1 | X12: 1 | Y12: 0 | Z12: 2 | AA12: =W12+X12+Y12+Z12 -> 4 | AB12: {=_xlfn.IFS(AND(AA12>=0,AA12<=15),"low purchase",AND(AA12>=16,AA12<=30),"mid purchase",AA12>=31,"high purchase")} -> low purchase | AC12: 7 | AD12: =IF(marketing_campaign[[#This Row],[NumWebVisitsMonth]]>=5.3,"higher_webvists","lower_webvisits") -> higher_webvists | AE12: 0 | AF12: 0 | AG12: 0 | AH12: 0 | AI12: 0 | AJ12: 0 | AK12: 3 | AL12: 11 | AM12: 0 | AN12: =marketing_campaign[[#This Row],[AcceptedCmp2]]+marketing_campaign[[#This Row],[AcceptedCmp1]]+marketing_campaign[[#This Row],[AcceptedCmp5]]+marketing_campaign[[#This Row],[AcceptedCmp4]]+marketing_campaign[[#This Row],[AcceptedCmp3]]+marketing_campaign[[#This Row],[Response]] -> 0 | AO12: {=_xlfn.IFS(marketing_campaign[[#This Row],[CampaignAccepted]]=0,"low response",marketing_campaign[[#This Row],[CampaignAccepted]]=1,"1 / 5 response accepted",marketing_campaign[[#This Row],[CampaignAccepted]]=2,"2/5 campaign accepted",marketing_campaign[[#This Row],[CampaignAccepted]]=3,"3/5 campaign accepted",marketing_campaign[[#This Row],[CampaignAccepted]]=4,"4/5 campaign accepted",marketing_campaign[[#This Row],[CampaignAccepted]]=5,"high campaign response")} -> low response
A13: 387 | B13: 1976 | C13: =YEAR(TODAY())-B13 -> 50 | D13: {=_xlfn.IFS(AND(marketing_campaign[[#This Row],[Age]]>=30,marketing_campaign[[#This Row],[Age]]<=45),"30-45 Youth",AND(marketing_campaign[[#This Row],[Age]]>=46,marketing_campaign[[#This Row],[Age]]<=61),"46-61 Old",AND(marketing_campaign[[#This Row],[Age]]>=62,marketing_campaign[[#This Row],[Age]]<=77),"62-77 Snr Citizen",AND(marketing_campaign[[#This Row],[Age]]>=78,marketing_campaign[[#This Row],[Age]]<=133),"78-133 Elder")} -> 46-61 Old | E13: Basic | F13: Married | G13: {=_xlfn.IFS(marketing_campaign[[#This Row],[Marital_Status]]="Single",K13+L13+1,marketing_campaign[[#This Row],[Marital_Status]]="Together",K13+L13+2,marketing_campaign[[#This Row],[Marital_Status]]="Alone",K13+L13+1,marketing_campaign[[#This Row],[Marital_Status]]="Married",K13+L13+2,marketing_campaign[[#This Row],[Marital_Status]]="Divorced",K13+L13+1,marketing_campaign[[#This Row],[Marital_Status]]="YOLO",K13+L13+1,marketing_campaign[[#This Row],[Marital_Status]]="Absurd",K13+L13+1,marketing_campaign[[#This Row],[Marital_Status]]="Widow",K13+L13+1)} -> 2 | H13: {=_xlfn.IFS(marketing_campaign[[#This Row],[Family_size]]=1,"Family_with_one_child",marketing_campaign[[#This Row],[Family_size]]>1,"Family_with_more_children")} -> Family_with_more_children | I13: 7500 | J13: =IF(marketing_campaign[[#This Row],[Income]]>=Sheet21!B63,"high_income","low_income") -> high_income | K13: 0 | L13: 0 | M13: 41226 | N13: 59 | O13: {=_xlfn.IFS(AND(marketing_campaign[[#This Row],[Recency]]>=0,marketing_campaign[[#This Row],[Recency]]<=14),"Early Recency",AND(marketing_campaign[[#This Row],[Recency]]>=15,marketing_campaign[[#This Row],[Recency]]<=31),"Mid-Recency",marketing_campaign[[#This Row],[Recency]]>=32,"high Recency")} -> high Recency | P13: 6 | Q13: 16 | R13: 11 | S13: 11 | T13: 1 | U13: 16 | V13: =marketing_campaign[[#This Row],[MntGoldProds]]+marketing_campaign[[#This Row],[MntSweetProducts]]+marketing_campaign[[#This Row],[MntFishProducts]]+marketing_campaign[[#This Row],[MntMeatProducts]]+marketing_campaign[[#This Row],[MntFruits]]+marketing_campaign[[#This Row],[MntWines]] -> 61 | W13: 1 | X13: 2 | Y13: 0 | Z13: 3 | AA13: =W13+X13+Y13+Z13 -> 6 | AB13: {=_xlfn.IFS(AND(AA13>=0,AA13<=15),"low purchase",AND(AA13>=16,AA13<=30),"mid purchase",AA13>=31,"high purchase")} -> low purchase | AC13: 8 | AD13: =IF(marketing_campaign[[#This Row],[NumWebVisitsMonth]]>=5.3,"higher_webvists","lower_webvisits") -> higher_webvists | AE13: 0 | AF13: 0 | AG13: 0 | AH13: 0 | AI13: 0 | AJ13: 0 | AK13: 3 | AL13: 11 | AM13: 0 | AN13: =marketing_campaign[[#This Row],[AcceptedCmp2]]+marketing_campaign[[#This Row],[AcceptedCmp1]]+marketing_campaign[[#This Row],[AcceptedCmp5]]+marketing_campaign[[#This Row],[AcceptedCmp4]]+marketing_campaign[[#This Row],[AcceptedCmp3]]+marketing_campaign[[#This Row],[Response]] -> 0 | AO13: {=_xlfn.IFS(marketing_campaign[[#This Row],[CampaignAccepted]]=0,"low response",marketing_campaign[[#This Row],[CampaignAccepted]]=1,"1 / 5 response accepted",marketing_campaign[[#This Row],[CampaignAccepted]]=2,"2/5 campaign accepted",marketing_campaign[[#This Row],[CampaignAccepted]]=3,"3/5 campaign accepted",marketing_campaign[[#This Row],[CampaignAccepted]]=4,"4/5 campaign accepted",marketing_campaign[[#This Row],[CampaignAccepted]]=5,"high campaign response")} -> low response
